Workbook
Name Capa: '[1]IVI QA Staff Evaluation'!$C$15:$C$66
Name Capa_by_ID: "OFFSET('Raw Individual'!A4:AC8400,MATCH('Raw Individual'!L4,'Raw Individual'!A4:AC4,0),1,COUNTIF('Raw Individual'!A:A,'Mentee Schedule'!B1),1)"
Name Capa_Main: '[2]Raw Individual'!$M$5:$M$13600
Name chart_Capa_M12: OFFSET('[2]DB Mentee'!$AA$26,,,COUNTIF('[2]DB Mentee'!$AA$26:$AA$35,"<>"&"-"),)
Name Chart_Capa_M3: OFFSET('[2]DB Mentee'!$R$26,,,COUNTIF('[2]DB Mentee'!$R$26:$R$35,"<>"&"-"),)
Name Chart_Capa_M6: OFFSET('[2]DB Mentee'!$U$26,,,COUNTIF('[2]DB Mentee'!$U$26:$U$35,"<>"&"-"),)
Name Chart_Capa_M9: OFFSET('[2]DB Mentee'!$X$26,,,COUNTIF('[2]DB Mentee'!$X$26:$X$35,"<>"&"-"),)
Name Chart_Mentee: OFFSET('[2]DB Mentee'!$C$26,,,COUNTIF('[2]DB Mentee'!$C$26:$C$35,"<>"&"-"),)
Name data: OFFSET('[3]QA list'!$A$2,,,COUNTA('[3]QA list'!$A$2:$A$9894),7)
Name data1: OFFSET('[3]QA list'!$A$2,0,0,COUNTA('[3]QA list'!$A$2:$A$9901),7)
Name data2: OFFSET('[3]QA list'!$B$2,0,0,COUNTA('[3]QA list'!$B$2:$B$9901),7)
Name Emp_no: OFFSET('[3]QA list'!$B$2,,,COUNTA('[3]QA list'!$B$2:$B$9894))
Name hangmuc: #REF!
Name Mentee_ID: '[2]Raw Individual'!$A$5:$A$13600
Name Mentor_ID: '[2]Raw Individual'!$J$5:$J$13600
Name Part: '[1]IVI QA Staff Evaluation'!$B$15:$B$66
Name QAEmp_List: #REF!
Name Sub_Capa: '[2]Raw Individual'!$N$5:$N$13600
Name training: OFFSET('[4]Training history'!$A$1,,,COUNTA('[4]Training history'!$A$1:$A$10010),COUNTA('[4]Training history'!$A$1:$W$1))

Sheet Capability set up
B2: Function | C2: Div | D2: Team | E2: Capability | F2: Sub-Capability | G2: Common/ Specific | H2: Available online course | I2: Convert Online Training (Y/N) | J2: Training document | K2: Must know Index/ Knowledge & Calculation logic | L2: Learning Schedule | M2: Remark
B3: MFG | E3: Production planning | F3: Establishing production plans according to the system | L3: M7
B4: MFG | E4: =E3 -> Production planning | F4: Line operation ratio check | L4: M3
B5: MFG | E5: =E4 -> Production planning | F5: Min H/C, Max Capacity checks | L5: M9
B6: MFG | E6: =E5 -> Production planning | F6: Understanding and management of POR/PCR | L6: M2
B7: MFG | E7: Production status management | F7: Understanding of Production process | L7: M1
B8: MFG | E8: =E7 -> Production status management | F8: W/O completion rate management | L8: M8
B9: MFG | E9: =E8 -> Production status management | F9: UPH management | K9: • UPH = Production Qty / Direct Manpower • Efficiency = Yield ManHour / Net ManHour • UPPH1 • UPPH2 • Yeild rate | L9: M11
B10: MFG | E10: =E9 -> Production status management | F10: UPPH(1,2,3) management | L10: M10
B11: MFG | E11: =E10 -> Production status management | F11: Monthly/weekly operational availability management | L11: M8
B12: MFG | E12: =E11 -> Production status management | F12: Production capacity analysis and management of man-hours | L12: M4
B13: MFG | E13: =E12 -> Production status management | F13: Management of personnel operations on the production line. | L13: M8
B14: MFG | E14: =E13 -> Production status management | F14: Weekly/daily TT Loss status and improvement | L14: M4
B15: MFG | E15: =E14 -> Production status management | F15: Understanding and management of Yield-rate | L15: M2
B16: MFG | E16: Productivity KPI management | F16: Productivity KPI and results/goals | L16: M3
B17: MFG | E17: =E16 -> Productivity KPI management | F17: Weekly status board | L17: M11
B18: MFG | E18: =E17 -> Productivity KPI management | F18: Monthly, weekly, daily reports | L18: M7
B19: MFG | E19: =E18 -> Productivity KPI management | F19: Understanding the calculation logic of productivity KPI | L19: M7
B20: MFG | E20: =E19 -> Productivity KPI management | F20: Methods for improving KPI indicators | L20: M3
B21: MFG | E21: =E20 -> Productivity KPI management | F21: Management of marginal defects and residual lots | L21: M4
B22: MFG | E22: Productivity improvement activities | F22: Analysis of ST, Yield-rate, UPPH, UPH | L22: M12
B23: MFG | E23: =E22 -> Productivity improvement activities | F23: Line capacity simulation and improvement | L23: M1
B24: MFG | E24: =E23 -> Productivity improvement activities | F24: LB analysis and improvement (Bottleneck process improvement) | L24: M4
B25: MFG | E25: =E24 -> Productivity improvement activities | F25: Production Line Loss analysis and improvement | L25: M4
B26: MFG | E26: =E25 -> Productivity improvement activities | F26: Manufacturing systems and logistics improvement | L26: M8
B27: MFG | E27: =E26 -> Productivity improvement activities | F27: Line Capacity management and improvement | L27: M9
B28: MFG | E28: Line Improvement | F28: Checklist management | L28: M11
B29: MFG | E29: =E28 -> Line Improvement | F29: Tools and Jig management | L29: M4
B30: MFG | E30: =E29 -> Line Improvement | F30: Andon device management | L30: M4
B31: MFG | E31: =E30 -> Line Improvement | F31: Rework management(Process compliance, List management) | L31: M8
B32: MFG | E32: =E31 -> Line Improvement | F32: Weekly, daily repair results documentation & management | L32: M12
B33: MFG | E33: =E32 -> Line Improvement | F33: Operation and management of MBOM | L33: M5
B34: MFG | E34: Line quality Control | F34: Self sequential inspection(SSI) management & improvement - SSI layout management - SSI execution manual - Quality analysis, management and evaluation | L34: M7
B35: MFG | E35: =E34 -> Line quality Control | F35: Time Check management | L35: M11
B36: MFG | E36: =E35 -> Line quality Control | F36: CTP, CTQ registration & management | L36: M2
B37: MFG | E37: =E36 -> Line quality Control | F37: Process defect rate management | L37: M9
B38: MFG | E38: =E37 -> Line quality Control | F38: Management of process disorder report | L38: M4
B39: MFG | E39: =E38 -> Line quality Control | F39: Management of Inspection Automation Rate | L39: M4
B40: MFG | E40: =E39 -> Line quality Control | F40: 4M change management | L40: M4
B41: MFG | E41: =E40 -> Line quality Control | F41: ECO management | L41: M6
...

Sheet Yêu cầu
A1: Yêu cầu điền đầy đủ những thông tin sau:
A3: STT | B3: Yêu cầu | C3: Cụ thể | D3: Remark | E3: Due date
A4: 1 | B4: Chuẩn bị danh sách tham gia & Set up lộ trình học cho từng người | C4: - Danh sách lịch học của newcomer join từ 01/2025 đến nay. - Với newcomer tuyển vào từ grade G1.2 trở lên, được phép bỏ tối đa 50% tổng số Sub Capa. | D4: Điền theo format có sẵn. Hướng dẫn chi tiết trong các sheet bên cạnh. | E4: 45933
A5: 2 | B5: Set up Quiz cho từng Sub Capa | C5: - Phân chia người dạy cho mỗi Sub capa | E5: 45933
A6: 3 | B6: Set up Quiz cho từng Sub Capa | C6: -Mỗi 1 Sub capa là 1 bài Quiz. Bài Quiz này Mentor sẽ thi sau khi học xong 1 bài Sub capa. - Mỗi Sub capa cần có tối thiểu 10 Quiz (05 câu manual, 05 câu tham số). - Câu hỏi cần phân cấp độ khó: Low (50%) – Mid (30%) – High (20%). | E6: 45936
A8: Những sheet bôi vàng là những sheet cần điền

Sheet Capa List
A1: Định nghĩa sheet | B1: Capa List là Raw data của các CAPA mà các Team đã gửi em.
B3: Function | C3: Div | D3: Team | E3: Capability | F3: Sub-Capability | G3: Common/ Specific | H3: Must know Index/ Knowledge & Calculation logic | I3: Learning Schedule | J3: Sử dụng video OJT | K3: Learrng date | L3: Mentor | M3: Name | N3: ID | O3: Mentee
B4: R&D | C4: IVI | D4: IVI LD 2 | E4: LD common knowledge | F4: Label design knowledge | G4: Specific | H4: - How to design label - System related - Trouble shooting | I4: M7 | J4: N | K4: 45848 | L4: thanhphuong.bui | M4: Bui Thanh Phuong | N4: VH007911 | O4: Khanh
B5: R&D | C5: IVI | D5: IVI LD 2 | E5: LD common knowledge | F5: Package understanding | G5: Specific | H5: - Understanding about basic of packing - layout of packing - information in packig planing | I5: M9 | J5: N | K5: 45910 | L5: quangtrung.vu | M5: Vu Quang Trung | N5: VH006067 | O5: Khanh
B6: R&D | C6: IVI | D6: IVI LD 2 | E6: LD common knowledge | F6: Regulation Check List | G6: Specific | H6: - Regulation meaning - Basic regulation on each country - How to check regualtion for specific model - Issue and action | I6: M12 | J6: N | K6: 45818 | L6: phuonganh.tran | M6: Tran Thi Phuong Anh | N6: VH03229 | O6: Khanh
B7: R&D | C7: IVI | D7: IVI LD 2 | E7: Mechanical understanding | F7: Die-casting knowledge | G7: Specific | H7: - Understanding about produtcion of Die-casting part - Understanding about Die-casting molds - Understanding about popular issue of Die-casting part/ root cause/ improve action | I7: M8 | J7: N | K7: 45879 | L7: minh01.pham | M7: Pham Hong Minh | N7: VH006670 | O7: -Duong - Long -Tham - Phuc - Gia Huy - Tuan
B8: R&D | C8: IVI | D8: IVI LD 2 | E8: Mechanical understanding | F8: Drawing knowledge | G8: Specific | H8: - How to read drawing basiclly - GD & T popular in drawing - Understanding about special dimension: DR, CC, SC, VM, CIC,.. | I8: M1 | J8: N | K8: 45667 | L8: quangtrung.vu | M8: Vu Quang Trung | N8: VH006067 | O8: -Duong - Long -Tham - Phuc - Gia Huy - Tuan Khanh
B9: R&D | C9: IVI | D9: IVI LD 2 | E9: Mechanical understanding | F9: Injection knowledge | G9: Specific | H9: - Understanding about produtcion of Injection part - Understanding about Injection molds - Understanding about popular issue of Injection part part/ root cause/ improve action | I9: M7 | J9: N | K9: 45853 | L9: quangtrung.vu | M9: Vu Quang Trung | N9: VH006067 | O9: -Tham - Phuc - Tuan
B10: R&D | C10: IVI | D10: IVI LD 2 | E10: Mechanical understanding | F10: Press knowledge | G10: Specific | H10: - Understanding about produtcion of Press part - Understanding about Press molds - Understanding about popular issue of Press part/ root cause/ improve action | I10: M6 | J10: N | K10: 45823 | L10: minh01.pham | M10: Pham Hong Minh | N10: VH006670 | O10: - Phuc - Gia Huy - Tuan
B11: R&D | C11: IVI | D11: IVI LD 2 | E11: Mechanical understanding | F11: Screw angle calculation | G11: Specific | H11: - How to verify screw angle spec / actual | I11: M9 | J11: N | K11: 45915 | L11: quangtrung.vu | M11: Vu Quang Trung | N11: VH006067 | O11: - Gia Huy - Tuan
B12: R&D | C12: IVI | D12: IVI LD 2 | E12: Mechanical understanding | F12: Screwing knowledge | G12: Specific | H12: - Understanding about produtcion of screw - Understanding about popular issue of Screw/ root cause/ improve action | I12: M5 | J12: N | K12: 45787 | L12: minh01.pham | M12: Pham Hong Minh | N12: VH006670 | O12: - Gia Huy - Tuan
B13: R&D | C13: IVI | D13: IVI LD 2 | E13: Mechanical understanding | F13: Stack up analysis & loop diagram | G13: Specific | H13: - Basiclly for stack up analysis - Which issue can apply this analysis standard | I13: M10 | J13: N | K13: 45940 | L13: quangtrung.vu | M13: Vu Quang Trung | N13: VH006067 | O13: -Duong - Long -Tham - Phuc - Gia Huy - Tuan
B14: R&D | C14: IVI | D14: IVI LD 2 | E14: Process understanding | F14: JIG verification and confirmation overview | G14: Specific | H14: - How to develop JIG in Dev stage - Process invest JIG / payment/ verify JIG - Set up in FA line - Transfer process | I14: M11 | J14: N | K14: 45757 | L14: minh01.pham | M14: Pham Hong Minh | N14: VH006670 | O14: -Duong - Long -Tham - Phuc - Gia Huy - Tuan
B15: R&D | C15: IVI | D15: IVI LD 2 | E15: Process understanding | F15: Local tooling development process | G15: Specific | H15: -Understanding process of local tool development - Payment process, - Control list | I15: M3 | J15: N | K15: 45726 | L15: quangtrung.vu | M15: Vu Quang Trung | N15: VH006067 | O15: -Duong - Long -Tham - Phuc - Gia Huy - Tuan
... B18: R&D | C18: IVI | D18: IVI LD 2 | E18: Process understanding | F18: Sample PO process | G18: Common | H18: - Different between sample PO -MP PO - How to calculate sample PO QTY - Process from event plan - Receive sample PO | I18: M4 | J18: N | K18: 45762 | L18: phuonganh.tran | M18: Tran Thi Phuong Anh | N18: VH03229 | O18: Khanh Duong - Long -Tham - Phuc - Gia Huy - Tuan
B19: R&D | C19: IVI | D19: IVI LD 2/ LD1 | E19: Advance Modular | F19: DfM activity management (DfM checktool, DfM idea/report) | G19: Common | I19: M8 | J19: N | K19: =L19 -> Follow LD1 | L19: Follow LD1 | M19: Follow LD1 | N19: Follow LD1 | O19: -Duong - Long -Tham - Phuc - Gia Huy - Tuan
B20: R&D | C20: IVI | D20: IVI LD 2/ LD1 | E20: Inspection System | F20: GMES - Global Manufacturing Execution System (Set optin/ Label spec …) | G20: Common | I20: M2 | J20: N | K20: =L20 -> Follow LD1 | L20: Follow LD1 | M20: Follow LD1 | N20: Follow LD1 | O20: Khanh
B21: R&D | C21: IVI | D21: IVI LD 2/ LD1 | E21: Inspection System | F21: KLAS - Key, Label and Sofware system (Key Management) | G21: Common | I21: M2 | J21: N | K21: =L21 -> Follow LD1 | L21: Follow LD1 | M21: Follow LD1 | N21: Follow LD1 | O21: Khanh
B22: R&D | C22: IVI | D22: IVI LD 2 | E22: LD common knowledge | F22: BOM understanding | G22: Common | H22: - Meaning of BOM, UIT, Supply type, QTY, designator - System interface and BOM interaction to production | I22: M1 | J22: N | K22: 45672 | L22: thanh01.nguyen | M22: Nguyen Thi Phuong Thanh | N22: VH005430 | O22: Khanh Duong - Long -Tham - Phuc - Gia Huy - Tuan
B23: R&D | C23: IVI | D23: IVI LD 2 | E23: LD common knowledge | F23: ECO understanding | G23: Common | H23: - ECO standard - How to make ECO: 11 ECO content need to check - ECO KPI | I23: M2 | J23: N | K23: 45703 | L23: thanh01.nguyen | M23: Nguyen Thi Phuong Thanh | N23: VH005430 | O23: Khanh Duong - Long -Tham - Phuc - Gia Huy - Tuan
B24: R&D | C24: IVI | D24: IVI LD 2 | E24: LD common knowledge | F24: LD KPI understanding | G24: Common | H24: - LD KPI and how to calculation - How to achieve KPI | I24: M8 | J24: N | K24: 45884 | L24: sang.dao | M24: Dao Cong Sang | N24: VH003865 | O24: Khanh -Duong - Long -Tham - Phuc - Gia Huy - Tuan
B25: R&D | C25: IVI | D25: IVI LD 2/PD | E25: Development | F25: IVI product basic understanding (CID/Cluster/AVN/AVS/Tele) | G25: Common | I25: M9 | J25: N | K25: =L25 -> Follow PD | L25: Follow PD | M25: Follow PD | N25: Follow PD | O25: Khanh Duong - Long -Tham - Phuc - Gia Huy - Tuan
B26: R&D | C26: IVI | D26: IVI LD 2/PD | E26: Development | F26: PD SOP : New project transfer standard | G26: Common | I26: M5 | J26: N | K26: =L26 -> Follow PD | L26: Follow PD | M26: Follow PD | N26: Follow PD | O26: Khanh Duong - Long -Tham - Phuc - Gia Huy - Tuan
B27: R&D | C27: IVI | D27: IVI LD 2/PD | E27: Sample Build Management | F27: 4M sample build process | G27: Common | I27: M4 | J27: N | K27: =L27 -> Follow PD | L27: Follow PD | M27: Follow PD | N27: Follow PD | O27: Khanh Duong - Long -Tham - Phuc - Gia Huy - Tuan
B28: R&D | C28: IVI | D28: IVI LD 2/PD | E28: Sample Build Management | F28: Buyer sample build process understanding | G28: Common | I28: M3 | J28: N | K28: =L28 -> Follow PD | L28: Follow PD | M28: Follow PD | N28: Follow PD | O28: Khanh Duong - Long -Tham - Phuc - Gia Huy - Tuan

Sheet Mapping Mentor - Mentee
A1: Định nghĩa sheet | B1: Newcomer List là file Newcomer join từ 1/1/2025 đến nay của các Team. Mọi người điển từ cột J > cột N giúp em ạ
A2: Lưu ý | B2: Với những Newcomer có kinh nghiệm (Từ grade 1.2 trở lên) và những Newcomer đã join từ trước tháng 8/2025, được bỏ tối đa 50% trên tổng số lượng CAPA sẽ học
B3: 1 Mentee học 50 bài thì mọi người viết mỗi bài là 1 dòng
A5: Đối tượng điền | B5: HRD | C5: HRD | D5: HRD | E5: HRD | F5: HRD | G5: HRD | I5: HRD | J5: Team Leader | K5: Team Leader | L5: Team Leader | M5: Team Leader | N5: Mentor | O5: Mentor
N6: Số tháng kinh nghiệm của Mentee làm việc tại LGEVH VD: M01, M02, M03 | O6: Tháng bắt đầu học trong năm VD: M01, M02, M03
B7: Mentee ID | C7: Mentee Name | D7: Org | E7: Team | F7: Div | G7: Function | H7: Mentee Type | I7: Hire | J7: Mentor ID | K7: Mentor Name | L7: Capability Name | M7: Sub-Capability Name | N7: Learning Plan | O7: Learning Date
A8: Example | B8: VH009863 | C8: DO THI ANH MAI | D8: LGEVHA.HR Development Team | E8: HRD | F8: Common | G8: HR | H8: Fresher | I8: 45923 | J8: VH001352 | K8: NGUYEN QUE ANH | L8: Employee Management | M8: Resignation/ Position Appointment | N8: M01 | O8: 45931
B9: VH100436 | C9: Nguyen Phuc Duong | D9: IVI LD Mechanic | E9: IVI LD 2 | F9: IVI | G9: R&D | H9: Fresher | I9: =VLOOKUP(B9,[5]Grid!$B:$AA,26,0) -> 45712 | J9: VH006067 | K9: Vu Quang Trung
B10: VH100520 | C10: Bui Van Long | D10: IVI LD Mechanic | E10: IVI LD 2 | F10: IVI | G10: R&D | H10: Non-Fresher | I10: =VLOOKUP(B10,[5]Grid!$B:$AA,26,0) -> 45726 | J10: VH006067 | K10: Vu Quang Trung
B11: VH100636 | C11: Do Thi Tham | D11: IVI LD Mechanic | E11: IVI LD 2 | F11: IVI | G11: R&D | H11: Non-Fresher | I11: =VLOOKUP(B11,[5]Grid!$B:$AA,26,0) -> 45782 | J11: VH006067 | K11: Vu Quang Trung
B12: VH100697 | C12: Duong Van Phuc | D12: IVI LD Mechanic | E12: IVI LD 2 | F12: IVI | G12: R&D | H12: Fresher | I12: =VLOOKUP(B12,[5]Grid!$B:$AA,26,0) -> 45820 | J12: VH006670 | K12: Pham Hong Minh
B13: VH100747 | C13: Tran Gia Huy | D13: IVI LD Mechanic | E13: IVI LD 2 | F13: IVI | G13: R&D | H13: Fresher | I13: =VLOOKUP(B13,[5]Grid!$B:$AA,26,0) -> 45861 | J13: VH006067 | K13: Vu Quang Trung
B14: VH100774 | C14: Luong Van Tuan | D14: IVI LD Mechanic | E14: IVI LD 2 | F14: IVI | G14: R&D | H14: Non-Fresher | I14: =VLOOKUP(B14,[5]Grid!$B:$AA,26,0) -> 45894 | J14: VH006670 | K14: Pham Hong Minh
N16: ="M"&(YEAR(O16)-YEAR(I16))*12+(MONTH(O16)-MONTH(I16)) -> M0
N17: 45936 | O17: 45936
B18: Mentee ID | C18: Mentee Name | D18: Org | E18: Team | F18: Div | G18: Function | H18: Mentee Type | I18: Hire | J18: Mentor ID | K18: Mentor Name | L18: Capability Name | M18: Sub-Capability Name | N18: Learning Plan | O18: Learning Date | P18: Learning Schedule | R18: Team | T18: OJT
B19: VH100520 | C19: Bui Van Long | D19: =VLOOKUP(C19,$C$9:$D$14,2,0) -> IVI LD Mechanic | E19: IVI LD 2 | F19: IVI | G19: R&D | H19: =VLOOKUP(C19,$C$9:$H$14,6,0) -> Non-Fresher | I19: =VLOOKUP(C19,$C$9:$I$14,7,0) -> 45726 | J19: =VLOOKUP(C19,$C$7:$J$14,8,0) -> VH006067 | K19: =VLOOKUP(C19,$C$7:$K$14,9,0) -> Vu Quang Trung | L19: Mechanical understanding | M19: Drawing knowledge | N19: ="M"&(DATEDIF(IF(DAY(I19)<15, I19, EOMONTH(I19,0)),O19,"m")+1) -> M1 | O19: =DATE(2025,T19,1) -> 45748 | P19: =VLOOKUP(M19,'Capa List'!F:I,4,0) -> M1 | Q19: =(YEAR(O19)-YEAR(I19))*12+(MONTH(O19)-MONTH(I19)) -> 1 | R19: =VLOOKUP(M19,'Capa List'!$F:$I,4,0) -> M1 | S19: =RIGHT(R19,1) -> 1 | T19: =MONTH(I19)+S19 -> 4 | U19: =N19=R19 -> TRUE
B20: VH100520 | C20: Bui Van Long | D20: =VLOOKUP(C20,$C$9:$D$14,2,0) -> IVI LD Mechanic | E20: IVI LD 2 | F20: IVI | G20: R&D | H20: =VLOOKUP(C20,$C$9:$H$14,6,0) -> Non-Fresher | I20: =VLOOKUP(C20,$C$9:$I$14,7,0) -> 45726 | J20: =VLOOKUP(C20,$C$7:$J$14,8,0) -> VH006067 | K20: =VLOOKUP(C20,$C$7:$K$14,9,0) -> Vu Quang Trung | L20: LD common knowledge | M20: BOM understanding | N20: ="M"&(DATEDIF(IF(DAY(I20)<15, I20, EOMONTH(I20,0)),O20,"m")+1) -> M1 | O20: =DATE(2025,T20,1) -> 45748 | P20: =VLOOKUP(M20,'Capa List'!F:I,4,0) -> M1 | Q20: =(YEAR(O20)-YEAR(I20))*12+(MONTH(O20)-MONTH(I20)) -> 1 | R20: =VLOOKUP(M20,'Capa List'!$F:$I,4,0) -> M1 | S20: =RIGHT(R20,1) -> 1 | T20: =MONTH(I20)+S20 -> 4 | U20: =N20=R20 -> TRUE
B21: VH100520 | C21: Bui Van Long | D21: =VLOOKUP(C21,$C$9:$D$14,2,0) -> IVI LD Mechanic | E21: IVI LD 2 | F21: IVI | G21: R&D | H21: =VLOOKUP(C21,$C$9:$H$14,6,0) -> Non-Fresher | I21: =VLOOKUP(C21,$C$9:$I$14,7,0) -> 45726 | J21: =VLOOKUP(C21,$C$7:$J$14,8,0) -> VH006067 | K21: =VLOOKUP(C21,$C$7:$K$14,9,0) -> Vu Quang Trung | L21: LD common knowledge | M21: ECO understanding | N21: ="M"&(DATEDIF(IF(DAY(I21)<15, I21, EOMONTH(I21,0)),O21,"m")+1) -> M2 | O21: =DATE(2025,T21,1) -> 45778 | P21: =VLOOKUP(M21,'Capa List'!F:I,4,0) -> M2 | Q21: =(YEAR(O21)-YEAR(I21))*12+(MONTH(O21)-MONTH(I21)) -> 2 | R21: =VLOOKUP(M21,'Capa List'!$F:$I,4,0) -> M2 | S21: =RIGHT(R21,1) -> 2 | T21: =MONTH(I21)+S21 -> 5 | U21: =N21=R21 -> TRUE
B22: VH100520 | C22: Bui Van Long | D22: =VLOOKUP(C22,$C$9:$D$14,2,0) -> IVI LD Mechanic | E22: IVI LD 2 | F22: IVI | G22: R&D | H22: =VLOOKUP(C22,$C$9:$H$14,6,0) -> Non-Fresher | I22: =VLOOKUP(C22,$C$9:$I$14,7,0) -> 45726 | J22: =VLOOKUP(C22,$C$7:$J$14,8,0) -> VH006067 | K22: =VLOOKUP(C22,$C$7:$K$14,9,0) -> Vu Quang Trung | L22: Process understanding | M22: Local tooling development process | N22: ="M"&(DATEDIF(IF(DAY(I22)<15, I22, EOMONTH(I22,0)),O22,"m")+1) -> M3 | O22: =DATE(2025,T22,1) -> 45809 | P22: =VLOOKUP(M22,'Capa List'!F:I,4,0) -> M3 | Q22: =(YEAR(O22)-YEAR(I22))*12+(MONTH(O22)-MONTH(I22)) -> 3 | R22: =VLOOKUP(M22,'Capa List'!$F:$I,4,0) -> M3 | S22: =RIGHT(R22,1) -> 3 | T22: =MONTH(I22)+S22 -> 6 | U22: =N22=R22 -> TRUE
B23: VH100520 | C23: Bui Van Long | D23: =VLOOKUP(C23,$C$9:$D$14,2,0) -> IVI LD Mechanic | E23: IVI LD 2 | F23: IVI | G23: R&D | H23: =VLOOKUP(C23,$C$9:$H$14,6,0) -> Non-Fresher | I23: =VLOOKUP(C23,$C$9:$I$14,7,0) -> 45726 | J23: =VLOOKUP(C23,$C$7:$J$14,8,0) -> VH006067 | K23: =VLOOKUP(C23,$C$7:$K$14,9,0) -> Vu Quang Trung | L23: Sample Build Management | M23: Buyer sample build process understanding | N23: ="M"&(DATEDIF(IF(DAY(I23)<15, I23, EOMONTH(I23,0)),O23,"m")+1) -> M3 | O23: =DATE(2025,T23,1) -> 45809 | P23: =VLOOKUP(M23,'Capa List'!F:I,4,0) -> M3 | Q23: =(YEAR(O23)-YEAR(I23))*12+(MONTH(O23)-MONTH(I23)) -> 3 | R23: =VLOOKUP(M23,'Capa List'!$F:$I,4,0) -> M3 | S23: =RIGHT(R23,1) -> 3 | T23: =MONTH(I23)+S23 -> 6 | U23: =N23=R23 -> TRUE
B24: VH100520 | C24: Bui Van Long | D24: =VLOOKUP(C24,$C$9:$D$14,2,0) -> IVI LD Mechanic | E24: IVI LD 2 | F24: IVI | G24: R&D | H24: =VLOOKUP(C24,$C$9:$H$14,6,0) -> Non-Fresher | I24: =VLOOKUP(C24,$C$9:$I$14,7,0) -> 45726 | J24: =VLOOKUP(C24,$C$7:$J$14,8,0) -> VH006067 | K24: =VLOOKUP(C24,$C$7:$K$14,9,0) -> Vu Quang Trung | L24: Process understanding | M24: Sample PO process | N24: ="M"&(DATEDIF(IF(DAY(I24)<15, I24, EOMONTH(I24,0)),O24,"m")+1) -> M4 | O24: =DATE(2025,T24,1) -> 45839 | P24: =VLOOKUP(M24,'Capa List'!F:I,4,0) -> M4 | Q24: =(YEAR(O24)-YEAR(I24))*12+(MONTH(O24)-MONTH(I24)) -> 4 | R24: =VLOOKUP(M24,'Capa List'!$F:$I,4,0) -> M4 | S24: =RIGHT(R24,1) -> 4 | T24: =MONTH(I24)+S24 -> 7 | U24: =N24=R24 -> TRUE
B25: VH100520 | C25: Bui Van Long | D25: =VLOOKUP(C25,$C$9:$D$14,2,0) -> IVI LD Mechanic | E25: IVI LD 2 | F25: IVI | G25: R&D | H25: =VLOOKUP(C25,$C$9:$H$14,6,0) -> Non-Fresher | I25: =VLOOKUP(C25,$C$9:$I$14,7,0) -> 45726 | J25: =VLOOKUP(C25,$C$7:$J$14,8,0) -> VH006067 | K25: =VLOOKUP(C25,$C$7:$K$14,9,0) -> Vu Quang Trung | L25: Sample Build Management | M25: 4M sample build process | N25: ="M"&(DATEDIF(IF(DAY(I25)<15, I25, EOMONTH(I25,0)),O25,"m")+1) -> M4 | O25: =DATE(2025,T25,1) -> 45839 | P25: =VLOOKUP(M25,'Capa List'!F:I,4,0) -> M4 | Q25: =(YEAR(O25)-YEAR(I25))*12+(MONTH(O25)-MONTH(I25)) -> 4 | R25: =VLOOKUP(M25,'Capa List'!$F:$I,4,0) -> M4 | S25: =RIGHT(R25,1) -> 4 | T25: =MONTH(I25)+S25 -> 7 | U25: =N25=R25 -> TRUE
B26: VH100520 | C26: Bui Van Long | D26: =VLOOKUP(C26,$C$9:$D$14,2,0) -> IVI LD Mechanic | E26: IVI LD 2 | F26: IVI | G26: R&D | H26: =VLOOKUP(C26,$C$9:$H$14,6,0) -> Non-Fresher | I26: =VLOOKUP(C26,$C$9:$I$14,7,0) -> 45726 | J26: =VLOOKUP(C26,$C$7:$J$14,8,0) -> VH006067 | K26: =VLOOKUP(C26,$C$7:$K$14,9,0) -> Vu Quang Trung | L26: Development | M26: PD SOP : New project transfer standard | N26: ="M"&(DATEDIF(IF(DAY(I26)<15, I26, EOMONTH(I26,0)),O26,"m")+1) -> M5 | O26: =DATE(2025,T26,1) -> 45870 | P26: =VLOOKUP(M26,'Capa List'!F:I,4,0) -> M5 | Q26: =(YEAR(O26)-YEAR(I26))*12+(MONTH(O26)-MONTH(I26)) -> 5 | R26: =VLOOKUP(M26,'Capa List'!$F:$I,4,0) -> M5 | S26: =RIGHT(R26,1) -> 5 | T26: =MONTH(I26)+S26 -> 8 | U26: =N26=R26 -> TRUE
B27: VH100520 | C27: Bui Van Long | D27: =VLOOKUP(C27,$C$9:$D$14,2,0) -> IVI LD Mechanic | E27: IVI LD 2 | F27: IVI | G27: R&D | H27: =VLOOKUP(C27,$C$9:$H$14,6,0) -> Non-Fresher | I27: =VLOOKUP(C27,$C$9:$I$14,7,0) -> 45726 | J27: =VLOOKUP(C27,$C$7:$J$14,8,0) -> VH006067 | K27: =VLOOKUP(C27,$C$7:$K$14,9,0) -> Vu Quang Trung | L27: LD common knowledge | M27: LD KPI understanding | N27: ="M"&(DATEDIF(IF(DAY(I27)<15, I27, EOMONTH(I27,0)),O27,"m")+1) -> M8 | O27: =DATE(2025,T27,1) -> 45962 | P27: =VLOOKUP(M27,'Capa List'!F:I,4,0) -> M8 | Q27: =(YEAR(O27)-YEAR(I27))*12+(MONTH(O27)-MONTH(I27)) -> 8 | R27: =VLOOKUP(M27,'Capa List'!$F:$I,4,0) -> M8 | S27: =RIGHT(R27,1) -> 8 | T27: =MONTH(I27)+S27 -> 11 | U27: =N27=R27 -> TRUE
B28: VH100520 | C28: Bui Van Long | D28: =VLOOKUP(C28,$C$9:$D$14,2,0) -> IVI LD Mechanic | E28: IVI LD 2 | F28: IVI | G28: R&D | H28: =VLOOKUP(C28,$C$9:$H$14,6,0) -> Non-Fresher | I28: =VLOOKUP(C28,$C$9:$I$14,7,0) -> 45726 | J28: =VLOOKUP(C28,$C$7:$J$14,8,0) -> VH006067 | K28: =VLOOKUP(C28,$C$7:$K$14,9,0) -> Vu Quang Trung | L28: Mechanical understanding | M28: Die-casting knowledge | N28: ="M"&(DATEDIF(IF(DAY(I28)<15, I28, EOMONTH(I28,0)),O28,"m")+1) -> M8 | O28: =DATE(2025,T28,1) -> 45962 | P28: =VLOOKUP(M28,'Capa List'!F:I,4,0) -> M8 | Q28: =(YEAR(O28)-YEAR(I28))*12+(MONTH(O28)-MONTH(I28)) -> 8 | R28: =VLOOKUP(M28,'Capa List'!$F:$I,4,0) -> M8 | S28: =RIGHT(R28,1) -> 8 | T28: =MONTH(I28)+S28 -> 11 | U28: =N28=R28 -> TRUE
B29: VH100520 | C29: Bui Van Long | D29: =VLOOKUP(C29,$C$9:$D$14,2,0) -> IVI LD Mechanic | E29: IVI LD 2 | F29: IVI | G29: R&D | H29: =VLOOKUP(C29,$C$9:$H$14,6,0) -> Non-Fresher | I29: =VLOOKUP(C29,$C$9:$I$14,7,0) -> 45726 | J29: =VLOOKUP(C29,$C$7:$J$14,8,0) -> VH006067 | K29: =VLOOKUP(C29,$C$7:$K$14,9,0) -> Vu Quang Trung | L29: Advance Modular | M29: DfM activity management (DfM checktool, DfM idea/report) | N29: ="M"&(DATEDIF(IF(DAY(I29)<15, I29, EOMONTH(I29,0)),O29,"m")+1) -> M8 | O29: =DATE(2025,T29,1) -> 45962 | P29: =VLOOKUP(M29,'Capa List'!F:I,4,0) -> M8 | Q29: =(YEAR(O29)-YEAR(I29))*12+(MONTH(O29)-MONTH(I29)) -> 8 | R29: =VLOOKUP(M29,'Capa List'!$F:$I,4,0) -> M8 | S29: =RIGHT(R29,1) -> 8 | T29: =MONTH(I29)+S29 -> 11 | U29: =N29=R29 -> TRUE
B30: VH100520 | C30: Bui Van Long | D30: =VLOOKUP(C30,$C$9:$D$14,2,0) -> IVI LD Mechanic | E30: IVI LD 2 | F30: IVI | G30: R&D | H30: =VLOOKUP(C30,$C$9:$H$14,6,0) -> Non-Fresher | I30: =VLOOKUP(C30,$C$9:$I$14,7,0) -> 45726 | J30: =VLOOKUP(C30,$C$7:$J$14,8,0) -> VH006067 | K30: =VLOOKUP(C30,$C$7:$K$14,9,0) -> Vu Quang Trung | L30: Development | M30: IVI product basic understanding (CID/Cluster/AVN/AVS/Tele) | N30: ="M"&(DATEDIF(IF(DAY(I30)<15, I30, EOMONTH(I30,0)),O30,"m")+1) -> M9 | O30: =DATE(2025,T30,1) -> 45992 | P30: =VLOOKUP(M30,'Capa List'!F:I,4,0) -> M9 | Q30: =(YEAR(O30)-YEAR(I30))*12+(MONTH(O30)-MONTH(I30)) -> 9 | R30: =VLOOKUP(M30,'Capa List'!$F:$I,4,0) -> M9 | S30: =RIGHT(R30,1) -> 9 | T30: =MONTH(I30)+S30 -> 12 | U30: =N30=R30 -> TRUE
B31: VH100520 | C31: Bui Van Long | D31: =VLOOKUP(C31,$C$9:$D$14,2,0) -> IVI LD Mechanic | E31: IVI LD 2 | F31: IVI | G31: R&D | H31: =VLOOKUP(C31,$C$9:$H$14,6,0) -> Non-Fresher | I31: =VLOOKUP(C31,$C$9:$I$14,7,0) -> 45726 | J31: =VLOOKUP(C31,$C$7:$J$14,8,0) -> VH006067 | K31: =VLOOKUP(C31,$C$7:$K$14,9,0) -> Vu Quang Trung | L31: Mechanical understanding | M31: Stack up analysis & loop diagram | N31: ="M"&(DATEDIF(IF(DAY(I31)<15, I31, EOMONTH(I31,0)),O31,"m")+1) -> M10 | O31: =DATE(2025,T31,1) -> 46023 | P31: =VLOOKUP(M31,'Capa List'!F:I,4,0) -> M10 | Q31: =(YEAR(O31)-YEAR(I31))*12+(MONTH(O31)-MONTH(I31)) -> 10 | R31: =VLOOKUP(M31,'Capa List'!$F:$I,4,0) -> M10 | S31: 10 | T31: =MONTH(I31)+S31 -> 13 | U31: =N31=R31 -> TRUE
B32: VH100520 | C32: Bui Van Long | D32: =VLOOKUP(C32,$C$9:$D$14,2,0) -> IVI LD Mechanic | E32: IVI LD 2 | F32: IVI | G32: R&D | H32: =VLOOKUP(C32,$C$9:$H$14,6,0) -> Non-Fresher | I32: =VLOOKUP(C32,$C$9:$I$14,7,0) -> 45726 | J32: =VLOOKUP(C32,$C$7:$J$14,8,0) -> VH006067 | K32: =VLOOKUP(C32,$C$7:$K$14,9,0) -> Vu Quang Trung | L32: Process understanding | M32: JIG verification and confirmation overview | N32: ="M"&(DATEDIF(IF(DAY(I32)<15, I32, EOMONTH(I32,0)),O32,"m")+1) -> M11 | O32: =DATE(2025,T32,1) -> 46054 | P32: =VLOOKUP(M32,'Capa List'!F:I,4,0) -> M11 | Q32: =(YEAR(O32)-YEAR(I32))*12+(MONTH(O32)-MONTH(I32)) -> 11 | R32: =VLOOKUP(M32,'Capa List'!$F:$I,4,0) -> M11 | S32: 11 | T32: =MONTH(I32)+S32 -> 14 | U32: =N32=R32 -> TRUE
B33: VH100636 | C33: Do Thi Tham | D33: =VLOOKUP(C33,$C$9:$D$14,2,0) -> IVI LD Mechanic | E33: IVI LD 2 | F33: IVI | G33: R&D | H33: =VLOOKUP(C33,$C$9:$H$14,6,0) -> Non-Fresher | I33: =VLOOKUP(C33,$C$9:$I$14,7,0) -> 45782 | J33: =VLOOKUP(C33,$C$7:$J$14,8,0) -> VH006067 | K33: =VLOOKUP(C33,$C$7:$K$14,9,0) -> Vu Quang Trung | L33: Mechanical understanding | M33: Drawing knowledge | N33: ="M"&(DATEDIF(IF(DAY(I33)<15, I33, EOMONTH(I33,0)),O33,"m")+1) -> M1 | O33: =DATE(2025,T33,1) -> 45809 | P33: =VLOOKUP(M33,'Capa List'!F:I,4,0) -> M1 | Q33: =(YEAR(O33)-YEAR(I33))*12+(MONTH(O33)-MONTH(I33)) -> 1 | R33: =VLOOKUP(M33,'Capa List'!$F:$I,4,0) -> M1 | S33: =RIGHT(R33,1) -> 1 | T33: =MONTH(I33)+S33 -> 6 | U33: =N33=R33 -> TRUE
B34: VH100636 | C34: Do Thi Tham | D34: =VLOOKUP(C34,$C$9:$D$14,2,0) -> IVI LD Mechanic | E34: IVI LD 2 | F34: IVI | G34: R&D | H34: =VLOOKUP(C34,$C$9:$H$14,6,0) -> Non-Fresher | I34: =VLOOKUP(C34,$C$9:$I$14,7,0) -> 45782 | J34: =VLOOKUP(C34,$C$7:$J$14,8,0) -> VH006067 | K34: =VLOOKUP(C34,$C$7:$K$14,9,0) -> Vu Quang Trung | L34: LD common knowledge | M34: BOM understanding | N34: ="M"&(DATEDIF(IF(DAY(I34)<15, I34, EOMONTH(I34,0)),O34,"m")+1) -> M1 | O34: =DATE(2025,T34,1) -> 45809 | P34: =VLOOKUP(M34,'Capa List'!F:I,4,0) -> M1 | Q34: =(YEAR(O34)-YEAR(I34))*12+(MONTH(O34)-MONTH(I34)) -> 1 | R34: =VLOOKUP(M34,'Capa List'!$F:$I,4,0) -> M1 | S34: =RIGHT(R34,1) -> 1 | T34: =MONTH(I34)+S34 -> 6 | U34: =N34=R34 -> TRUE
B35: VH100636 | C35: Do Thi Tham | D35: =VLOOKUP(C35,$C$9:$D$14,2,0) -> IVI LD Mechanic | E35: IVI LD 2 | F35: IVI | G35: R&D | H35: =VLOOKUP(C35,$C$9:$H$14,6,0) -> Non-Fresher | I35: =VLOOKUP(C35,$C$9:$I$14,7,0) -> 45782 | J35: =VLOOKUP(C35,$C$7:$J$14,8,0) -> VH006067 | K35: =VLOOKUP(C35,$C$7:$K$14,9,0) -> Vu Quang Trung | L35: LD common knowledge | M35: ECO understanding | N35: ="M"&(DATEDIF(IF(DAY(I35)<15, I35, EOMONTH(I35,0)),O35,"m")+1) -> M2 | O35: =DATE(2025,T35,1) -> 45839 | P35: =VLOOKUP(M35,'Capa List'!F:I,4,0) -> M2 | Q35: =(YEAR(O35)-YEAR(I35))*12+(MONTH(O35)-MONTH(I35)) -> 2 | R35: =VLOOKUP(M35,'Capa List'!$F:$I,4,0) -> M2 | S35: =RIGHT(R35,1) -> 2 | T35: =MONTH(I35)+S35 -> 7 | U35: =N35=R35 -> TRUE
B36: VH100636 | C36: Do Thi Tham | D36: =VLOOKUP(C36,$C$9:$D$14,2,0) -> IVI LD Mechanic | E36: IVI LD 2 | F36: IVI | G36: R&D | H36: =VLOOKUP(C36,$C$9:$H$14,6,0) -> Non-Fresher | I36: =VLOOKUP(C36,$C$9:$I$14,7,0) -> 45782 | J36: =VLOOKUP(C36,$C$7:$J$14,8,0) -> VH006067 | K36: =VLOOKUP(C36,$C$7:$K$14,9,0) -> Vu Quang Trung | L36: Process understanding | M36: Local tooling development process | N36: ="M"&(DATEDIF(IF(DAY(I36)<15, I36, EOMONTH(I36,0)),O36,"m")+1) -> M3 | O36: =DATE(2025,T36,1) -> 45870 | P36: =VLOOKUP(M36,'Capa List'!F:I,4,0) -> M3 | Q36: =(YEAR(O36)-YEAR(I36))*12+(MONTH(O36)-MONTH(I36)) -> 3 | R36: =VLOOKUP(M36,'Capa List'!$F:$I,4,0) -> M3 | S36: =RIGHT(R36,1) -> 3 | T36: =MONTH(I36)+S36 -> 8 | U36: =N36=R36 -> TRUE
B37: VH100636 | C37: Do Thi Tham | D37: =VLOOKUP(C37,$C$9:$D$14,2,0) -> IVI LD Mechanic | E37: IVI LD 2 | F37: IVI | G37: R&D | H37: =VLOOKUP(C37,$C$9:$H$14,6,0) -> Non-Fresher | I37: =VLOOKUP(C37,$C$9:$I$14,7,0) -> 45782 | J37: =VLOOKUP(C37,$C$7:$J$14,8,0) -> VH006067 | K37: =VLOOKUP(C37,$C$7:$K$14,9,0) -> Vu Quang Trung | L37: Sample Build Management | M37: Buyer sample build process understanding | N37: ="M"&(DATEDIF(IF(DAY(I37)<15, I37, EOMONTH(I37,0)),O37,"m")+1) -> M3 | O37: =DATE(2025,T37,1) -> 45870 | P37: =VLOOKUP(M37,'Capa List'!F:I,4,0) -> M3 | Q37: =(YEAR(O37)-YEAR(I37))*12+(MONTH(O37)-MONTH(I37)) -> 3 | R37: =VLOOKUP(M37,'Capa List'!$F:$I,4,0) -> M3 | S37: =RIGHT(R37,1) -> 3 | T37: =MONTH(I37)+S37 -> 8 | U37: =N37=R37 -> TRUE
B38: VH100636 | C38: Do Thi Tham | D38: =VLOOKUP(C38,$C$9:$D$14,2,0) -> IVI LD Mechanic | E38: IVI LD 2 | F38: IVI | G38: R&D | H38: =VLOOKUP(C38,$C$9:$H$14,6,0) -> Non-Fresher | I38: =VLOOKUP(C38,$C$9:$I$14,7,0) -> 45782 | J38: =VLOOKUP(C38,$C$7:$J$14,8,0) -> VH006067 | K38: =VLOOKUP(C38,$C$7:$K$14,9,0) -> Vu Quang Trung | L38: Process understanding | M38: Sample PO process | N38: ="M"&(DATEDIF(IF(DAY(I38)<15, I38, EOMONTH(I38,0)),O38,"m")+1) -> M4 | O38: =DATE(2025,T38,1) -> 45901 | P38: =VLOOKUP(M38,'Capa List'!F:I,4,0) -> M4 | Q38: =(YEAR(O38)-YEAR(I38))*12+(MONTH(O38)-MONTH(I38)) -> 4 | R38: =VLOOKUP(M38,'Capa List'!$F:$I,4,0) -> M4 | S38: =RIGHT(R38,1) -> 4 | T38: =MONTH(I38)+S38 -> 9 | U38: =N38=R38 -> TRUE
B39: VH100636 | C39: Do Thi Tham | D39: =VLOOKUP(C39,$C$9:$D$14,2,0) -> IVI LD Mechanic | E39: IVI LD 2 | F39: IVI | G39: R&D | H39: =VLOOKUP(C39,$C$9:$H$14,6,0) -> Non-Fresher | I39: =VLOOKUP(C39,$C$9:$I$14,7,0) -> 45782 | J39: =VLOOKUP(C39,$C$7:$J$14,8,0) -> VH006067 | K39: =VLOOKUP(C39,$C$7:$K$14,9,0) -> Vu Quang Trung | L39: Sample Build Management | M39: 4M sample build process | N39: ="M"&(DATEDIF(IF(DAY(I39)<15, I39, EOMONTH(I39,0)),O39,"m")+1) -> M4 | O39: =DATE(2025,T39,1) -> 45901 | P39: =VLOOKUP(M39,'Capa List'!F:I,4,0) -> M4 | Q39: =(YEAR(O39)-YEAR(I39))*12+(MONTH(O39)-MONTH(I39)) -> 4 | R39: =VLOOKUP(M39,'Capa List'!$F:$I,4,0) -> M4 | S39: =RIGHT(R39,1) -> 4 | T39: =MONTH(I39)+S39 -> 9 | U39: =N39=R39 -> TRUE
B40: VH100636 | C40: Do Thi Tham | D40: =VLOOKUP(C40,$C$9:$D$14,2,0) -> IVI LD Mechanic | E40: IVI LD 2 | F40: IVI | G40: R&D | H40: =VLOOKUP(C40,$C$9:$H$14,6,0) -> Non-Fresher | I40: =VLOOKUP(C40,$C$9:$I$14,7,0) -> 45782 | J40: =VLOOKUP(C40,$C$7:$J$14,8,0) -> VH006067 | K40: =VLOOKUP(C40,$C$7:$K$14,9,0) -> Vu Quang Trung | L40: Development | M40: PD SOP : New project transfer standard | N40: ="M"&(DATEDIF(IF(DAY(I40)<15, I40, EOMONTH(I40,0)),O40,"m")+1) -> M5 | O40: =DATE(2025,T40,1) -> 45931 | P40: =VLOOKUP(M40,'Capa List'!F:I,4,0) -> M5 | Q40: =(YEAR(O40)-YEAR(I40))*12+(MONTH(O40)-MONTH(I40)) -> 5 | R40: =VLOOKUP(M40,'Capa List'!$F:$I,4,0) -> M5 | S40: =RIGHT(R40,1) -> 5 | T40: =MONTH(I40)+S40 -> 10 | U40: =N40=R40 -> TRUE
B41: VH100636 | C41: Do Thi Tham | D41: =VLOOKUP(C41,$C$9:$D$14,2,0) -> IVI LD Mechanic | E41: IVI LD 2 | F41: IVI | G41: R&D | H41: =VLOOKUP(C41,$C$9:$H$14,6,0) -> Non-Fresher | I41: =VLOOKUP(C41,$C$9:$I$14,7,0) -> 45782 | J41: =VLOOKUP(C41,$C$7:$J$14,8,0) -> VH006067 | K41: =VLOOKUP(C41,$C$7:$K$14,9,0) -> Vu Quang Trung | L41: LD common knowledge | M41: LD KPI understanding | N41: ="M"&(DATEDIF(IF(DAY(I41)<15, I41, EOMONTH(I41,0)),O41,"m")+1) -> M8 | O41: =DATE(2025,T41,1) -> 46023 | P41: =VLOOKUP(M41,'Capa List'!F:I,4,0) -> M8 | Q41: =(YEAR(O41)-YEAR(I41))*12+(MONTH(O41)-MONTH(I41)) -> 8 | R41: =VLOOKUP(M41,'Capa List'!$F:$I,4,0) -> M8 | S41: =RIGHT(R41,1) -> 8 | T41: =MONTH(I41)+S41 -> 13 | U41: =N41=R41 -> TRUE
B42: VH100636 | C42: Do Thi Tham | D42: =VLOOKUP(C42,$C$9:$D$14,2,0) -> IVI LD Mechanic | E42: IVI LD 2 | F42: IVI | G42: R&D | H42: =VLOOKUP(C42,$C$9:$H$14,6,0) -> Non-Fresher | I42: =VLOOKUP(C42,$C$9:$I$14,7,0) -> 45782 | J42: =VLOOKUP(C42,$C$7:$J$14,8,0) -> VH006067 | K42: =VLOOKUP(C42,$C$7:$K$14,9,0) -> Vu Quang Trung | L42: Mechanical understanding | M42: Injection knowledge | N42: ="M"&(DATEDIF(IF(DAY(I42)<15, I42, EOMONTH(I42,0)),O42,"m")+1) -> M7 | O42: =DATE(2025,T42,1) -> 45992 | P42: =VLOOKUP(M42,'Capa List'!F:I,4,0) -> M7 | Q42: =(YEAR(O42)-YEAR(I42))*12+(MONTH(O42)-MONTH(I42)) -> 7 | R42: =VLOOKUP(M42,'Capa List'!$F:$I,4,0) -> M7 | S42: =RIGHT(R42,1) -> 7 | T42: =MONTH(I42)+S42 -> 12 | U42: =N42=R42 -> TRUE
...

Sheet Câu hỏi manual (5 câu)
A1: Định nghĩa sheet | B1: File upload câu hỏi dạng lý thuyết
B3: Capa | C3: Sub Capa | E3: Question | F3: Correct | G3: Answer A | H3: Answer B | I3: Answer C | J3: Answer D
A4: Format
A5: Example | B5: Basic Rule | C5: LGEVH Regulation | E5: Mức kỷ luật nặng nhất tại công ty là gì? | F5: D | G5: Khiển trách | H5: Cắt thưởng | I5: Cảnh cáo | J5: Sa thải
E6: Công thức đúng để tính UPPH là gì
B11: Capa | C11: Sub Capa | D11: Level | E11: Question | F11: Correct | G11: Answer A | H11: Answer B | I11: Answer C | J11: Answer D | K11: Mentor
B12: LD common knowledge | C12: BOM understanding | D12: Low | E12: BOM có mấy loại? | F12: C | G12: 1-MBOM | H12: 1-EBOM | I12: 2-MBOM và EBOM | J12: Không có đáp án đúng | K12: thanh01.nguyen
B13: LD common knowledge | C13: BOM understanding | D13: Low | E13: UIT của model là gì? | F13: A | G13: F, Q | H13: Q, X | I13: F, T | J13: T, P | K13: thanh01.nguyen
B14: LD common knowledge | C14: BOM understanding | D14: Low | E14: Đâu là UIT của vật liệu nội địa? | F14: C | G14: M | H14: D | I14: G | J14: R | K14: thanh01.nguyen
B15: LD common knowledge | C15: BOM understanding | D15: Mid | E15: Kết hợp nào giữa UIT và supply type sau đây không đúng? | F15: D | G15: X-Supplier | H15: G-Supplier | I15: T-Assemply pull | J15: R-supplier | K15: thanh01.nguyen
B16: LD common knowledge | C16: BOM understanding | D16: Low | E16: Nếu part mẹ là D-assemply pull, part con có thể là gì? | F16: B | G16: T-assemply pull | H16: D-supplier | I16: P-supplier | J16: X-supplier | K16: thanh01.nguyen
B17: LD common knowledge | C17: BOM understanding | D17: Mid | E17: Mối model suffix được release tại VH bao nhiêu lần | F17: D | G17: Tối đa 2 lần | H17: 3 lần | I17: nhiều lần | J17: 1 lần | K17: thanh01.nguyen
B18: LD common knowledge | C18: BOM understanding | D18: High | E18: VH release model có suffix là gì | F18: B | G18: .B | H18: .B và.T | I18: .T và .N | J18: .A và .B | K18: thanh01.nguyen
B19: LD common knowledge | C19: BOM understanding | D19: High | E19: Giải thích ý nghĩa của cụm Cover Assembly,Bottom | F19: C | G19: LG mua toàn bộ part con trong cụm Cover Assembly,Bottom | H19: LG mua toàn bộ part con, chuyển sang nhà cung cấp lắp ráp và trả phí gia công | I19: Nhà cung cấp mua toàn bộ part con và lắp ráp, LG mua lại cả cụm Cover Assembly,Bottom | J19: Không đáp án nào đúng | K19: thanh01.nguyen
B20: LD common knowledge | C20: BOM understanding | D20: Mid | E20: UIT và supply type của part trong VH BOM có giống HQ không | F20: B | G20: Bắt buộc phải giống HQ BOM | H20: Set up tùy thuộc vào cách thức sản xuất/ mua bán tại VH | I20: Set up dựa vào việc trao đổi giữa VH và HQ | J20: Đáp án B và C | K20: thanh01.nguyen
B21: Mechanical understanding | C21: Drawing knowledge | K21: quangtrung.vu
B22: Mechanical understanding | C22: Drawing knowledge | K22: quangtrung.vu
B23: Mechanical understanding | C23: Drawing knowledge | K23: quangtrung.vu
B24: Mechanical understanding | C24: Drawing knowledge | K24: quangtrung.vu
B25: Mechanical understanding | C25: Drawing knowledge | K25: quangtrung.vu
B26: LD common knowledge | C26: ECO understanding | D26: Low | E26: Đâu là số ECO? | F26: D | G26: EWVPA00023 | H26: LWVP200018 | I26: SKGP900181 | J26: Cả A và C | K26: thanh01.nguyen
B27: LD common knowledge | C27: ECO understanding | D27: Low | E27: Temporary ECO có làm thay đổi BOM trên NPDM không | F27: B | G27: Có | H27: Không | I27: Làm thay đổi BOM trong 1 ngày | J27: Làm thay đổi BOM cho đến thông báo tiếp theo | K27: thanh01.nguyen
B28: LD common knowledge | C28: ECO understanding | D28: Low | E28: Leadtime VH ECO từ khi HQ ECO done là bao lâu | F28: B | G28: 7 ngày | H28: 10 ngày | I28: 12 ngày | J28: 15 ngày | K28: thanh01.nguyen
B29: LD common knowledge | C29: ECO understanding | D29: Mid | E29: Khi cần thay đổi suppy type của part từ Phantom -> Assembly pull cần làm gì | F29: A | G29: Làm VH ECO internal | H29: Đổi trực tiếp trên hệ thống NPDM | I29: Yêu cầu HQ làm ECO đổi | J29: Làm trên hệ thống GERP | K29: thanh01.nguyen
B30: LD common knowledge | C30: ECO understanding | D30: Low | E30: Có thể kiểm tra chi tiết line approval của ECO ở mục nào | F30: A | G30: LifeCycle | H30: Affected Part | I30: ECO Working List | J30: Relationships | K30: thanh01.nguyen
B31: LD common knowledge | C31: ECO understanding | D31: Mid | E31: Từ VH ECO, có thể kiểm tra HQ ECO trực tiếp không | F31: B | G31: Không thể, cần check với HQ | H31: Có thể check trong VH ECO, mục Relationships | I31: Có thể check trên hệ thống GERP | J31: Cả B và C đúng | K31: thanh01.nguyen
B32: LD common knowledge | C32: ECO understanding | D32: High | E32: 2 site của VH ECO là gì | F32: D | G32: VH_Car Infortainment Division và KR_Vehicle Engineering ADAS Division | H32: AZ_Car Audio Parts Division và VH_Vehicle Engineering ADAS Division | I32: AZ_Car Audio Parts Division và NV_CAR_Infortainment_Division | J32: VH_Car Infortainment Division và VH_Vehicle Engineering ADAS Division | K32: thanh01.nguyen
B33: LD common knowledge | C33: ECO understanding | D33: High | E33: Khi VH cần thay đổi design của part, đâu là process đúng | F33: B | G33: VH ECO -> thông báo cho HQ -> thông báo cho nhà cung cấp | H33: VH ECR -> HQ ECO -> VH ECO | I33: Yêu cầu nhà cung cấp thay đổi deassign thông qua email confirm | J33: VH làm EP approval xin đổi design | K33: thanh01.nguyen
B34: LD common knowledge | C34: ECO understanding | D34: Mid | E34: VH được tự làm ECO trong trường hợp nào | F34: C | G34: Không được phép | H34: Khi kế hoạch sản suất quá gấp | I34: Khi sửa supply type của part trong BOM | J34: Khi HQ yêu cầu | K34: thanh01.nguyen
B35: LD common knowledge | C35: ECO understanding | D35: Low | E35: Đâu là cách tìm kiếm ECO trên hệ thống NPDM | F35: A | G35: NPDM -> Search -> Change -> Release & ECO | H35: NPDM -> Search -> Change -> ECO | I35: NPDM -> Search -> Change -> ECR | J35: NPDM -> Find -> Change -> ECO | K35: thanh01.nguyen
B36: Mechanical understanding | C36: Injection knowledge | K36: quangtrung.vu
B37: Mechanical understanding | C37: Injection knowledge | K37: quangtrung.vu
B38: Mechanical understanding | C38: Injection knowledge | K38: quangtrung.vu
B39: Mechanical understanding | C39: Injection knowledge | K39: quangtrung.vu
B40: Mechanical understanding | C40: Injection knowledge | K40: quangtrung.vu
B41: LD common knowledge | C41: Label design knowledge | D41: Low | E41: Có mấy loại label được thường được in trên FA | F41: D | G41: 1 | H41: 2 | I41: 3 | J41: 4 | K41: thanhphuong.bui
B42: LD common knowledge | C42: Label design knowledge | D42: Mid | E42: Label spec trên GMES được dung để làm gì ? | F42: C | G42: Quản lí KHSX | H42: Theo dõi tình trạng SX | I42: Quản lí thông tin di động tem | J42: Quản lí design tem | K42: thanhphuong.bui
B43: LD common knowledge | C43: Label design knowledge | D43: Mid | E43: Khi phát triển thông tin mới di động, bạn cần phải làm gì ? | F43: D | G43: Check xem thông tin đó link DID file hay hệ thống link auto | H43: Check với HQ xem ý nghĩ thông tin đó | I43: Tạo thiết kế và in thử nhãn, kiểm tra thực tế | J43: Tất cả đều đúng | K43: thanhphuong.bui
B44: LD common knowledge | C44: Label design knowledge | D44: Low | E44: Mục đích của Tem wip là gì ? | F44: A | G44: Đánh dấu công đoạn – Input và Complete. Từng trạm đều phải scan tem này | H44: In main label | I44: In box label | J44: Lưu lại lịch sử KHSX | K44: thanhphuong.bui
B45: LD common knowledge | C45: Label design knowledge | D45: Mid | E45: Khi có new project được release trong BOM, việc đầu tiên cần làm về label là gì ? | F45: B | G45: Yêu cầu HQ cập nhật bản vẽ label | H45: kiểm tra BOM của model đó xem có đủ P/N của 3 loại tem chính chưa trước | I45: Thiết kế label và in thử | J45: Kiểm tra kế hoạch sản xuất để chuẩn bị thông tin label | K45: thanhphuong.bui
...

Sheet Câu hỏi tham số (5 câu)
A1: Định nghĩa sheet | B1: File upload câu hỏi dạng tham số
B4: Capa | C4: Sub Capa | D4: Level | E4: Question | F4: Parameter | G4: Formular
A5: Format | E5: Câu hỏi có tham số | F5: Tham số a: [...], [...], [...] Tham số b: [...], [...], [...] | G5: = a + b
A6: Example | B6: Toán học | C6: Cộng số nguyên dương | D6: Low | E6: [A] + [B] bằng bao nhiêu? | F6: [A]:1-5/1 [B]:10,20,30 | G6: A+B
B7: Kỹ năng | C7: Kỹ năng mềm | D7: Mid | E7: Tính diện tích hình chữ nhật có chiều dài [L] và rộng [W] | F7: [L]:2-4/1 [W]:5,10 | G7: L*W
B8: Bảo hiểm | C8: Bảo hiểm xã hội | D8: High | E8: Một người lao động Việt Nam làm việc theo hợp đồng không xác định thời hạn tại doanh nghiệp trong nước, có mức lương tháng là [a] đồng. Doanh nghiệp đóng BHXH, BHYT, BHTN theo đúng mức quy định hiện hành. Mức lương tối thiểu vùng áp dụng là [b] đồng. Hỏi: Tổng số tiền mà người lao động phải trích nộp hàng tháng cho các khoản BHXH, BHYT, BHTN là bao nhiêu? | F8: [a]: 4,000,000-10,000,000/2,000,000 [b]: 1,000,000-3,000,000/500,000 | G8: =[8%[a]]+[1.5%x[a]]]+[1%x[b]]
B18: Quy định:
B19: - Trong câu hỏi phải có tham số, công thức tính ra đáp án bằng các tham số đó
B20: - Số lượng câu hỏi: Mỗi sub capa có ít nhất 10 câu hỏi. Trong mỗi sub capa có tối thiểu 5 câu hỏi manual, 5 câu hỏi logic. Trường hợp không đủ câu hỏi logic thì bù bằng câu hỏi manual
B21: - Tỷ lệ level: Low, Mid, High
B23: Capa | C23: Sub Capa | D23: Level | E23: Question | F23: Parameter | G23: Formular | H23: Mentor
B24: LD common knowledge | C24: BOM understanding | D24: Low | E24: Nếu số lượng pallet trong BOM là [a], vậy có bao nhiêu set/pallet | F24: Tham số a: 0.125, 0.25 | G24: =1/a | H24: thanh01.nguyen
B25: LD common knowledge | C25: BOM understanding | D25: Low | E25: Trong BOM, part*có số lượng [a], được mua nội địa với giá [b] VND, tỉ giá VND/USD = 0.000037 -> tính giá trong BOM cost ($) | F25: Tham số a: 15,20,30 Tham bố b: 0,00569;0,047;0,00258 | G25: =a*b*0.000037 | H25: thanh01.nguyen
B26: Mechanical understanding | C26: Drawing knowledge | H26: quangtrung.vu
B27: Mechanical understanding | C27: Drawing knowledge | H27: quangtrung.vu
B28: Mechanical understanding | C28: Drawing knowledge | H28: quangtrung.vu
B29: Mechanical understanding | C29: Drawing knowledge | H29: quangtrung.vu
B30: Mechanical understanding | C30: Drawing knowledge | H30: quangtrung.vu
B31: Mechanical understanding | C31: Injection knowledge | H31: quangtrung.vu
B32: Mechanical understanding | C32: Injection knowledge | H32: quangtrung.vu
B33: Mechanical understanding | C33: Injection knowledge | H33: quangtrung.vu
B34: Mechanical understanding | C34: Injection knowledge | H34: quangtrung.vu
B35: Mechanical understanding | C35: Injection knowledge | H35: quangtrung.vu
B36: LD common knowledge | C36: Label design knowledge | D36: Mid | E36: Trong BOM, P/N 3850R-S048G có qty là [a]. Mỗi box dán [b] label. Tính số lượng set [c] trong box | F36: [a]:0.5, 0.6, 0.7 [b]:2,3,4 | G36: = b/a | H36: thanhphuong.bui
B37: LD common knowledge | C37: Label design knowledge | D37: Mid | E37: P/N MEZ65147612 có qty trong BOM là [a], mỗi set dán [b] nhãn này.Tính số lượng nhãn cần dán thực tế | F37: [a]:0.25,0.5, 0.2 [b]:2,4,6,8, | G37: = b/a | H37: thanhphuong.bui
B38: LD common knowledge | C38: Label design knowledge | D38: High | E38: P/N ribbon MGY6264320B có qty trong BOM là [a]. Ribbon là [b] Tính qty [c] khi in cho 1000ea label | F38: [a]:0.1, 0.105, 0.2,0.3 [b]:1000,1200,1400 [c]: 0.5,0.6,0.7 | G38: =[a*b] + c | H38: thanhphuong.bui
B39: LD common knowledge | C39: Label design knowledge | D39: Low | E39: Một con set của JLR FCD nặng kg [a]. Packing là [b]. Có [c] set trong box Tính GROSS WEIGHT của box full set | F39: [a]:2.00, 3.00, 4.00 [b]:0.89, 0.90 , 0.91 [c]:4,5,6 | G39: =[a+b]*c | H39: thanhphuong.bui
B40: LD common knowledge | C40: LD KPI understanding | D40: LOW | E40: Một chuyền có sản lượng sản xuất trong tháng là [a], số lượng sản phẩm lỗi là [b], vậy tỉ lê defect (ppm) của chuyền đó là bao nhiêu? | F40: [a] 10,000~100,000/1000 [b] 10~500/10 | G40: =([b]/[a])*10^6 | H40: sang.dao
B41: LD common knowledge | C41: LD KPI understanding | D41: HIGH | E41: Model A hoàn thành PV Pgate vào ngày 1/5 (1.May), sản xuất lần 1 vào 10.5 với sản lượng là [a], số lượng lỗi là [x]; ngày 20.6 với số lượng là [b], số lượng lỗi [y]. Tính chỉ số New model quality M+3 của model đó. | F41: [a] 10,000~100,000/1000 [b] 10,000~100,000/1000 [x] 10~500/10 [y] 10~500/10 | G41: =([x+y]/[a+b])*10^6 | H41: sang.dao
B42: LD common knowledge | C42: LD KPI understanding | D42: HIGH | E42: Biêt thời gian dừng chuyền do lỗi trờn ren là [a] tiếng, chuyền có [b] headcount, tổng direct manhour của chuyền tháng ấy là [c] (h). Vậy idle time rate của lỗi này trong tháng bằng bao nhiêu %? | F42: [a] 0.5~10/0.5 [b] 10~30/1 [c] 4000~10000/1000 | G42: =[[a]*[b]/[c]]*100% | H42: sang.dao
B43: LD common knowledge | C43: LD KPI understanding | D43: MID | E43: Biết tháng 8 phòng LD2 có 5 lỗi với thời gian phân tích lần lượt là [a], [b], [c], [d], [e] ngày, tính lead time analysis của phòng LD2 trong tháng 8? | F43: [a,b,c,d,e] 0~5/1 | G43: =[a+b+c+d+e]/5 | H43: sang.dao
B44: LD common knowledge | C44: LD KPI understanding | D44: HIGH | E44: Biêết tháng 8 có [a] BOM và [b] ECO được thực hiện (release), trong đó có [x] ECO không đạt leadtime, hỏi chỉ số BOM/ECO leadtime tháng 8 là bao nhiêu %? | F44: [a,b] 100~200/1 [x] 1~10/1 | G44: =[a+b-x]/[a+b] *100% | H44: sang.dao
B45: Process understanding | C45: Local tooling development process | H45: quangtrung.vu
B46: Process understanding | C46: Local tooling development process | H46: quangtrung.vu
B47: Process understanding | C47: Local tooling development process | H47: quangtrung.vu
B48: Process understanding | C48: Local tooling development process | H48: quangtrung.vu
B49: Process understanding | C49: Local tooling development process | H49: quangtrung.vu
B50: Process understanding | C50: New development process | H50: quangtrung.vu
B51: Process understanding | C51: New development process | H51: quangtrung.vu
B52: Process understanding | C52: New development process | H52: quangtrung.vu
...

Sheet Level
A1: ID | B1: NAME | C1: Part | D1: CAPA_NAME | E1: Initial level | F1: Target 2026 | Q1: =1/12 -> 0.083333333
F2: Jan | G2: Feb | H2: Mar | I2: Apr | J2: May | K2: Jun | L2: Jul | M2: Aug | N2: Sep | Q2: Hire
A3: =VLOOKUP(B3,[6]HC!B:C,2,0) -> VH100520 | B3: BUI VAN LONG | C3: MEC | D3: Technical understanding | E3: 1.5 | F3: =G3-$Q$1 -> 1.8333333 | G3: =H3-$Q$1 -> 1.9166667 | H3: 2 | I3: =H3+0.05 -> 2.05 | J3: =I3+0.05 -> 2.1 | K3: =J3+0.05 -> 2.15 | L3: =K3+0.05 -> 2.2 | M3: =L3+0.05 -> 2.25 | N3: =M3+0.05 -> 2.3 | O3: =N3-E3 -> 0.8 | P3: =ROUNDDOWN(O3/8,2) -> 0.09 | Q3: 45726 | R3: =9-MONTH(Q3) -> 6 | S3: cappa trên 3 cả năm tăng 0.3
A4: =VLOOKUP(B4,[6]HC!B:C,2,0) -> VH100520 | B4: BUI VAN LONG | C4: MEC | D4: Process understanding | E4: 1.5 | F4: =G4-$Q$1 -> 1.8333333 | G4: =H4-$Q$1 -> 1.9166667 | H4: 2 | I4: =H4+0.05 -> 2.05 | J4: =I4+0.05 -> 2.1 | K4: =J4+0.05 -> 2.15 | L4: =K4+0.05 -> 2.2 | M4: =L4+0.05 -> 2.25 | N4: =M4+0.05 -> 2.3 | O4: =N4-E4 -> 0.8 | P4: =ROUNDDOWN(O4/8,2) -> 0.09 | Q4: 45726 | R4: =9-MONTH(Q4) -> 6 | S4: trên 2 tăng 0.5
A5: =VLOOKUP(B5,[6]HC!B:C,2,0) -> VH100636 | B5: DO THI THAM | C5: MEC | D5: Technical understanding | E5: 0.5 | F5: =G5-$Q$1 -> 0.66666667 | G5: =H5-$Q$1 -> 0.75 | H5: =I5-$Q$1 -> 0.83333333 | I5: =J5-$Q$1 -> 0.91666667 | J5: 1 | K5: =J5+0.05 -> 1.05 | L5: =K5+0.05 -> 1.1 | M5: =L5+0.05 -> 1.15 | N5: =M5+0.05 -> 1.2 | O5: =N5-E5 -> 0.7 | P5: =ROUNDDOWN(O5/8,2) -> 0.08 | Q5: 45782 | R5: =9-MONTH(Q5) -> 4 | S5: dưới 2 tăng lên 1
A6: =VLOOKUP(B6,[6]HC!B:C,2,0) -> VH100636 | B6: DO THI THAM | C6: MEC | D6: Process understanding | E6: 0.5 | F6: =G6-$Q$1 -> 0.66666667 | G6: =H6-$Q$1 -> 0.75 | H6: =I6-$Q$1 -> 0.83333333 | I6: =J6-$Q$1 -> 0.91666667 | J6: 1 | K6: =J6+0.05 -> 1.05 | L6: =K6+0.05 -> 1.1 | M6: =L6+0.05 -> 1.15 | N6: =M6+0.05 -> 1.2 | O6: =N6-E6 -> 0.7 | P6: =ROUNDDOWN(O6/8,2) -> 0.08 | Q6: 45782 | R6: =9-MONTH(Q6) -> 4
A7: =VLOOKUP(B7,[6]HC!B:C,2,0) -> VH100697 | B7: DUONG VAN PHUC | C7: MEC | D7: Technical understanding | E7: =R7*$Q$1 -> 0.25 | F7: =G7-$Q$1 -> 0.58333333 | G7: =H7-$Q$1 -> 0.66666667 | H7: =I7-$Q$1 -> 0.75 | I7: =J7-$Q$1 -> 0.83333333 | J7: =K7-$Q$1 -> 0.91666667 | K7: 1 | L7: =K7+0.05 -> 1.05 | M7: =L7+0.05 -> 1.1 | N7: =M7+0.05 -> 1.15 | O7: =N7-E7 -> 0.9 | P7: =ROUNDDOWN(O7/8,2) -> 0.11 | Q7: 45820 | R7: =9-MONTH(Q7) -> 3
A8: =VLOOKUP(B8,[6]HC!B:C,2,0) -> VH100697 | B8: DUONG VAN PHUC | C8: MEC | D8: Process understanding | E8: =R8*$Q$1 -> 0.25 | F8: =G8-$Q$1 -> 0.58333333 | G8: =H8-$Q$1 -> 0.66666667 | H8: =I8-$Q$1 -> 0.75 | I8: =J8-$Q$1 -> 0.83333333 | J8: =K8-$Q$1 -> 0.91666667 | K8: 1 | L8: =K8+0.05 -> 1.05 | M8: =L8+0.05 -> 1.1 | N8: =M8+0.05 -> 1.15 | O8: =N8-E8 -> 0.9 | P8: =ROUNDDOWN(O8/8,2) -> 0.11 | Q8: 45820 | R8: =9-MONTH(Q8) -> 3
A9: =VLOOKUP(B9,[6]HC!B:C,2,0) -> VH100436 | B9: NGUYEN PHUC DUONG | C9: MEC | D9: Technical understanding | E9: =R9*$Q$1 -> 0.58333333 | F9: =G9-$Q$1 -> 0.91666667 | G9: 1 | H9: =G9+0.05 -> 1.05 | I9: =H9+0.05 -> 1.1 | J9: =I9+0.05 -> 1.15 | K9: =J9+0.05 -> 1.2 | L9: =K9+0.05 -> 1.25 | M9: =L9+0.05 -> 1.3 | N9: =M9+0.05 -> 1.35 | O9: =N9-E9 -> 0.76666667 | P9: =ROUNDDOWN(O9/8,2) -> 0.09 | Q9: 45712 | R9: =9-MONTH(Q9) -> 7
A10: =VLOOKUP(B10,[6]HC!B:C,2,0) -> VH100436 | B10: NGUYEN PHUC DUONG | C10: MEC | D10: Process understanding | E10: =R10*$Q$1 -> 0.58333333 | F10: =G10-$Q$1 -> 0.91666667 | G10: 1 | H10: =G10+0.05 -> 1.05 | I10: =H10+0.05 -> 1.1 | J10: =I10+0.05 -> 1.15 | K10: =J10+0.05 -> 1.2 | L10: =K10+0.05 -> 1.25 | M10: =L10+0.05 -> 1.3 | N10: =M10+0.05 -> 1.35 | O10: =N10-E10 -> 0.76666667 | P10: =ROUNDDOWN(O10/8,2) -> 0.09 | Q10: 45712 | R10: =9-MONTH(Q10) -> 7
A11: =VLOOKUP(B11,[6]HC!B:C,2,0) -> VH100747 | B11: TRAN GIA HUY | C11: MEC | D11: Technical understanding | E11: =R11*$Q$1 -> 0.16666667 | F11: =G11-$Q$1 -> 0.5 | G11: =H11-$Q$1 -> 0.58333333 | H11: =I11-$Q$1 -> 0.66666667 | I11: =J11-$Q$1 -> 0.75 | J11: =K11-$Q$1 -> 0.83333333 | K11: =L11-$Q$1 -> 0.91666667 | L11: 1 | M11: =L11+0.05 -> 1.05 | N11: =M11+0.05 -> 1.1 | O11: =N11-E11 -> 0.93333333 | P11: =ROUNDDOWN(O11/8,2) -> 0.11 | Q11: 45861 | R11: =9-MONTH(Q11) -> 2
A12: =VLOOKUP(B12,[6]HC!B:C,2,0) -> VH100747 | B12: TRAN GIA HUY | C12: MEC | D12: Process understanding | E12: =R12*$Q$1 -> 0.16666667 | F12: =G12-$Q$1 -> 0.5 | G12: =H12-$Q$1 -> 0.58333333 | H12: =I12-$Q$1 -> 0.66666667 | I12: =J12-$Q$1 -> 0.75 | J12: =K12-$Q$1 -> 0.83333333 | K12: =L12-$Q$1 -> 0.91666667 | L12: 1 | M12: =L12+0.05 -> 1.05 | N12: =M12+0.05 -> 1.1 | O12: =N12-E12 -> 0.93333333 | P12: =ROUNDDOWN(O12/8,2) -> 0.11 | Q12: 45861 | R12: =9-MONTH(Q12) -> 2
A13: =VLOOKUP(B13,[6]HC!B:C,2,0) -> VH100774 | B13: LUONG VAN TUAN | C13: MEC | D13: Technical understanding | E13: 0.1 | F13: =G13-$Q$1 -> 0.41666667 | G13: =H13-$Q$1 -> 0.5 | H13: =I13-$Q$1 -> 0.58333333 | I13: =J13-$Q$1 -> 0.66666667 | J13: =K13-$Q$1 -> 0.75 | K13: =L13-$Q$1 -> 0.83333333 | L13: =M13-$Q$1 -> 0.91666667 | M13: 1 | N13: =M13+0.05 -> 1.05 | O13: =N13-E13 -> 0.95 | P13: =ROUNDDOWN(O13/8,2) -> 0.11 | Q13: 45894 | R13: =9-MONTH(Q13) -> 1
A14: =VLOOKUP(B14,[6]HC!B:C,2,0) -> VH100774 | B14: LUONG VAN TUAN | C14: MEC | D14: Process understanding | E14: 0.1 | F14: =G14-$Q$1 -> 0.41666667 | G14: =H14-$Q$1 -> 0.5 | H14: =I14-$Q$1 -> 0.58333333 | I14: =J14-$Q$1 -> 0.66666667 | J14: =K14-$Q$1 -> 0.75 | K14: =L14-$Q$1 -> 0.83333333 | L14: =M14-$Q$1 -> 0.91666667 | M14: 1 | N14: =M14+0.05 -> 1.05 | O14: =N14-E14 -> 0.95 | P14: =ROUNDDOWN(O14/8,2) -> 0.11 | Q14: 45894 | R14: =9-MONTH(Q14) -> 1
